<?xml version="1.0" encoding="utf-8"?>
<!-- This URDF was automatically created by SolidWorks to URDF Exporter! Originally created by Stephen Brawner (brawner@gmail.com) 
     Commit Version:   Build Version: 1.6.9177.32434
     For more information, please see http://wiki.ros.org/sw_urdf_exporter -->
<robot
  name="tail">
  <link
    name="base_link">
    <inertial>
      <origin
        xyz="-0.0246546252283572 -0.0150156534448461 0.00837382744618125"
        rpy="0 0 0" />
      <mass
        value="0.142896121980389" />
      <inertia
        ixx="0.000172848056043176"
        ixy="-2.56147282967753E-07"
        ixz="-9.21158957979319E-09"
        iyy="0.000139660707244487"
        iyz="-2.60840607484691E-06"
        izz="0.000290099857074405" />
    </inertial>
    <visual>
      <origin
        xyz="0 0 0"
        rpy="0 0 0" />
      <geometry>
        <mesh
          filename="package://tail/meshes/base_link.STL" />
      </geometry>
      <material
        name="">
        <color
          rgba="0.792156862745098 0.819607843137255 0.933333333333333 1" />
      </material>
    </visual>
    <collision>
      <origin
        xyz="0 0 0"
        rpy="0 0 0" />
      <geometry>
        <mesh
          filename="package://tail/meshes/base_link.STL" />
      </geometry>
    </collision>
  </link>
  <link
    name="link1-virtual">
  </link>
  <joint
    name="joint1-virtual"
    type="continuous">
    <origin
      xyz="0.0 0 0"
      rpy="0 0 0" />
    <parent
      link="base_link" />
    <child
      link="link1-virtual" />
    <axis
      xyz="0 1 0" />
  </joint>
  <link
    name="link1">
    <inertial>
      <origin
        xyz="2.08166817117217E-17 1.07552855510562E-16 0.001"
        rpy="0 0 0" />
      <mass
        value="0.00240331837999615" />
      <inertia
        ixx="2.45269832602438E-07"
        ixy="5.9311449081908E-22"
        ixz="-7.57306469012188E-27"
        iyy="2.45269832602435E-07"
        iyz="8.83524213847455E-27"
        izz="4.88937452951542E-07" />
    </inertial>
    <visual>
      <origin
        xyz="0 0 0"
        rpy="0 0 0" />
      <geometry>
        <mesh
          filename="package://tail/meshes/link1.STL" />
      </geometry>
      <material
        name="">
        <color
          rgba="0.792156862745098 0.819607843137255 0.933333333333333 1" />
      </material>
    </visual>
    <collision>
      <origin
        xyz="0 0 0"
        rpy="0 0 0" />
      <geometry>
        <mesh
          filename="package://tail/meshes/link1.STL" />
      </geometry>
    </collision>
  </link>
  <joint
    name="joint1"
    type="continuous">
    <origin
      xyz="0.03 0 0"
      rpy="0 0 0" />
    <parent
      link="link1-virtual" />
    <child
      link="link1" />
    <axis
      xyz="0 0 1" />
  </joint>
  <link
    name="link2-virtual">
  </link>
  <joint
    name="joint2-virtual"
    type="continuous">
    <origin
      xyz="0.0 0 0"
      rpy="0 0 0" />
    <parent
      link="link1" />
    <child
      link="link2-virtual" />
    <axis
      xyz="0 1 0" />
  </joint>
  <link
    name="link2">
    <inertial>
      <origin
        xyz="2.08166817117217E-17 1.07552855510562E-16 0.00100000000000001"
        rpy="0 0 0" />
      <mass
        value="0.00240331837999615" />
      <inertia
        ixx="2.45269832602438E-07"
        ixy="5.93316439210817E-22"
        ixz="-7.57306469012188E-27"
        iyy="2.45269832602435E-07"
        iyz="8.83524213847455E-27"
        izz="4.88937452951542E-07" />
    </inertial>
    <visual>
      <origin
        xyz="0 0 0"
        rpy="0 0 0" />
      <geometry>
        <mesh
          filename="package://tail/meshes/link2.STL" />
      </geometry>
      <material
        name="">
        <color
          rgba="0.792156862745098 0.819607843137255 0.933333333333333 1" />
      </material>
    </visual>
    <collision>
      <origin
        xyz="0 0 0"
        rpy="0 0 0" />
      <geometry>
        <mesh
          filename="package://tail/meshes/link2.STL" />
      </geometry>
    </collision>
  </link>
  <joint
    name="joint2"
    type="continuous">
    <origin
      xyz="0.03 0 0"
      rpy="0 0 0" />
    <parent
      link="link2-virtual" />
    <child
      link="link2" />
    <axis
      xyz="0 0 1" />
  </joint>
  <link
    name="link3-virtual">
  </link>
  <joint
    name="joint3-virtual"
    type="continuous">
    <origin
      xyz="0.0 0 0"
      rpy="0 0 0" />
    <parent
      link="link2" />
    <child
      link="link3-virtual" />
    <axis
      xyz="0 1 0" />
  </joint>
  <link
    name="link3">
    <inertial>
      <origin
        xyz="2.08166817117217E-17 1.0842021724855E-16 0.000999999999999987"
        rpy="0 0 0" />
      <mass
        value="0.00240331837999613" />
      <inertia
        ixx="2.45269832602436E-07"
        ixy="5.92811568231475E-22"
        ixz="-1.48305850177636E-26"
        iyy="2.45269832602433E-07"
        iyz="-1.27795466627806E-26"
        izz="4.88937452951538E-07" />
    </inertial>
    <visual>
      <origin
        xyz="0 0 0"
        rpy="0 0 0" />
      <geometry>
        <mesh
          filename="package://tail/meshes/link3.STL" />
      </geometry>
      <material
        name="">
        <color
          rgba="0.792156862745098 0.819607843137255 0.933333333333333 1" />
      </material>
    </visual>
    <collision>
      <origin
        xyz="0 0 0"
        rpy="0 0 0" />
      <geometry>
        <mesh
          filename="package://tail/meshes/link3.STL" />
      </geometry>
    </collision>
  </link>
  <joint
    name="joint3"
    type="continuous">
    <origin
      xyz="0.03 0 0"
      rpy="0 0 0" />
    <parent
      link="link3-virtual" />
    <child
      link="link3" />
    <axis
      xyz="0 0 1" />
  </joint>
  <link
    name="link4-virtual">
  </link>
  <joint
    name="joint4-virtual"
    type="continuous">
    <origin
      xyz="0.0 0 0"
      rpy="0 0 0" />
    <parent
      link="link3" />
    <child
      link="link4-virtual" />
    <axis
      xyz="0 1 0" />
  </joint>
  <link
    name="link4">
    <inertial>
      <origin
        xyz="2.08166817117217E-17 1.07552855510562E-16 0.001"
        rpy="0 0 0" />
      <mass
        value="0.00240331837999615" />
      <inertia
        ixx="2.45269832602438E-07"
        ixy="5.9311449081908E-22"
        ixz="-7.57306469012188E-27"
        iyy="2.45269832602435E-07"
        iyz="8.83524213847455E-27"
        izz="4.88937452951542E-07" />
    </inertial>
    <visual>
      <origin
        xyz="0 0 0"
        rpy="0 0 0" />
      <geometry>
        <mesh
          filename="package://tail/meshes/link4.STL" />
      </geometry>
      <material
        name="">
        <color
          rgba="0.792156862745098 0.819607843137255 0.933333333333333 1" />
      </material>
    </visual>
    <collision>
      <origin
        xyz="0 0 0"
        rpy="0 0 0" />
      <geometry>
        <mesh
          filename="package://tail/meshes/link4.STL" />
      </geometry>
    </collision>
  </link>
  <joint
    name="joint4"
    type="continuous">
    <origin
      xyz="0.03 0 0"
      rpy="0 0 0" />
    <parent
      link="link4-virtual" />
    <child
      link="link4" />
    <axis
      xyz="0 0 1" />
  </joint>
  <link
    name="link5-virtual">
  </link>
  <joint
    name="joint5-virtual"
    type="continuous">
    <origin
      xyz="0.0 0 0"
      rpy="0 0 0" />
    <parent
      link="link4" />
    <child
      link="link5-virtual" />
    <axis
      xyz="0 1 0" />
  </joint>
  <link
    name="link5">
    <inertial>
      <origin
        xyz="-0.001 5.98479599211998E-17 -6.93889390390723E-18"
        rpy="0 0 0" />
      <mass
        value="0.00134617245206321" />
      <inertia
        ixx="1.56230813614397E-07"
        ixy="3.786532345048E-27"
        ixz="7.57306469012369E-27"
        iyy="7.85641309578857E-08"
        iyz="-1.06426802445178E-22"
        izz="7.85641309578864E-08" />
    </inertial>
    <visual>
      <origin
        xyz="0 0 0"
        rpy="0 0 0" />
      <geometry>
        <mesh
          filename="package://tail/meshes/link5.STL" />
      </geometry>
      <material
        name="">
        <color
          rgba="0.792156862745098 0.819607843137255 0.933333333333333 1" />
      </material>
    </visual>
    <collision>
      <origin
        xyz="0 0 0"
        rpy="0 0 0" />
      <geometry>
        <mesh
          filename="package://tail/meshes/link5.STL" />
      </geometry>
    </collision>
  </link>
  <joint
    name="joint5"
    type="continuous">
    <origin
      xyz="0.03 0 0"
      rpy="0 0 0" />
    <parent
      link="link5-virtual" />
    <child
      link="link5" />
    <axis
      xyz="0 0 1" />
  </joint>
  <link
    name="link6-virtual">
  </link>
  <joint
    name="joint6-virtual"
    type="continuous">
    <origin
      xyz="0.0 0 0"
      rpy="0 0 0" />
    <parent
      link="link5" />
    <child
      link="link6-virtual" />
    <axis
      xyz="0 1 0" />
  </joint>
  <link
    name="link6">
    <inertial>
      <origin
        xyz="-0.000999999999999973 5.98479599211998E-17 -6.93889390390723E-18"
        rpy="0 0 0" />
      <mass
        value="0.00134617245206321" />
      <inertia
        ixx="1.56230813614397E-07"
        ixy="3.786532345048E-27"
        ixz="7.57306469012369E-27"
        iyy="7.85641309578857E-08"
        iyz="-1.06426802445178E-22"
        izz="7.85641309578864E-08" />
    </inertial>
    <visual>
      <origin
        xyz="0 0 0"
        rpy="0 0 0" />
      <geometry>
        <mesh
          filename="package://tail/meshes/link6.STL" />
      </geometry>
      <material
        name="">
        <color
          rgba="0.792156862745098 0.819607843137255 0.933333333333333 1" />
      </material>
    </visual>
    <collision>
      <origin
        xyz="0 0 0"
        rpy="0 0 0" />
      <geometry>
        <mesh
          filename="package://tail/meshes/link6.STL" />
      </geometry>
    </collision>
  </link>
  <joint
    name="joint6"
    type="continuous">
    <origin
      xyz="0.03 0 0"
      rpy="0 0 0" />
    <parent
      link="link6-virtual" />
    <child
      link="link6" />
    <axis
      xyz="0 0 1" />
  </joint>
  <link
    name="link7-virtual">
  </link>
  <joint
    name="joint7-virtual"
    type="continuous">
    <origin
      xyz="0.0 0 0"
      rpy="0 0 0" />
    <parent
      link="link6" />
    <child
      link="link7-virtual" />
    <axis
      xyz="0 1 0" />
  </joint>
  <link
    name="link7">
    <inertial>
      <origin
        xyz="-0.001 9.80118763926896E-17 -1.73472347597681E-17"
        rpy="0 0 0" />
      <mass
        value="0.00083723444218166" />
      <inertia
        ixx="6.23317507912513E-08"
        ixy="3.78653234505031E-27"
        ixz="7.57306469012324E-27"
        iyy="3.14449535430192E-08"
        iyz="-1.06376315347244E-22"
        izz="3.14449535430199E-08" />
    </inertial>
    <visual>
      <origin
        xyz="0 0 0"
        rpy="0 0 0" />
      <geometry>
        <mesh
          filename="package://tail/meshes/link7.STL" />
      </geometry>
      <material
        name="">
        <color
          rgba="0.792156862745098 0.819607843137255 0.933333333333333 1" />
      </material>
    </visual>
    <collision>
      <origin
        xyz="0 0 0"
        rpy="0 0 0" />
      <geometry>
        <mesh
          filename="package://tail/meshes/link7.STL" />
      </geometry>
    </collision>
  </link>
  <joint
    name="joint7"
    type="continuous">
    <origin
      xyz="0.03 0 0"
      rpy="0 0 0" />
    <parent
      link="link7-virtual" />
    <child
      link="link7" />
    <axis
      xyz="0 0 1" />
  </joint>
  <link
    name="link8-virtual">
  </link>
  <joint
    name="joint8-virtual"
    type="continuous">
    <origin
      xyz="0.0 0 0"
      rpy="0 0 0" />
    <parent
      link="link7" />
    <child
      link="link8-virtual" />
    <axis
      xyz="0 1 0" />
  </joint>
  <link
    name="link8">
    <inertial>
      <origin
        xyz="-0.001 9.80118763926896E-17 -1.73472347597681E-17"
        rpy="0 0 0" />
      <mass
        value="0.00083723444218166" />
      <inertia
        ixx="6.23317507912513E-08"
        ixy="3.78653234505015E-27"
        ixz="7.57306469012327E-27"
        iyy="3.14449535430192E-08"
        iyz="-1.06376315347244E-22"
        izz="3.14449535430199E-08" />
    </inertial>
    <visual>
      <origin
        xyz="0 0 0"
        rpy="0 0 0" />
      <geometry>
        <mesh
          filename="package://tail/meshes/link8.STL" />
      </geometry>
      <material
        name="">
        <color
          rgba="0.792156862745098 0.819607843137255 0.933333333333333 1" />
      </material>
    </visual>
    <collision>
      <origin
        xyz="0 0 0"
        rpy="0 0 0" />
      <geometry>
        <mesh
          filename="package://tail/meshes/link8.STL" />
      </geometry>
    </collision>
  </link>
  <joint
    name="joint8"
    type="continuous">
    <origin
      xyz="0.03 0 0"
      rpy="0 0 0" />
    <parent
      link="link8-virtual" />
    <child
      link="link8" />
    <axis
      xyz="0 0 1" />
  </joint>
  <link
    name="link9-virtual">
  </link>
  <joint
    name="joint9-virtual"
    type="continuous">
    <origin
      xyz="0.0 0 0"
      rpy="0 0 0" />
    <parent
      link="link8" />
    <child
      link="link9-virtual" />
    <axis
      xyz="0 1 0" />
  </joint>
  <link
    name="link9">
    <inertial>
      <origin
        xyz="-0.000999999999999945 9.80118763926896E-17 -1.73472347597681E-17"
        rpy="0 0 0" />
      <mass
        value="0.00083723444218166" />
      <inertia
        ixx="6.23317507912513E-08"
        ixy="3.78653234505015E-27"
        ixz="7.57306469012327E-27"
        iyy="3.14449535430192E-08"
        iyz="-1.06376315347244E-22"
        izz="3.14449535430199E-08" />
    </inertial>
    <visual>
      <origin
        xyz="0 0 0"
        rpy="0 0 0" />
      <geometry>
        <mesh
          filename="package://tail/meshes/link9.STL" />
      </geometry>
      <material
        name="">
        <color
          rgba="0.792156862745098 0.819607843137255 0.933333333333333 1" />
      </material>
    </visual>
    <collision>
      <origin
        xyz="0 0 0"
        rpy="0 0 0" />
      <geometry>
        <mesh
          filename="package://tail/meshes/link9.STL" />
      </geometry>
    </collision>
  </link>
  <joint
    name="joint9"
    type="continuous">
    <origin
      xyz="0.03 0 0"
      rpy="0 0 0" />
    <parent
      link="link9-virtual" />
    <child
      link="link9" />
    <axis
      xyz="0 0 1" />
  </joint>
</robot>